<robot name="dyros_jet_robot">

  <link name="world"/>
  <joint name = "virtual" type="floating">
    <origin xyz="0 0 0" rpy="0 0 0" />
    <parent link ="world"/>
    <child link="base_link"/>
    <limit effort="200" velocity="1.0" lower="-3.14" upper="3.14"/>
  </joint>

  <link name="base_link">
    <inertial>
      <origin xyz="0 0 0.08027" rpy="0 0 0" />
      <mass value="3.90994" />
      <inertia
        ixx="0.02724195938"
        ixy="0"
        ixz="0"
        iyy="0.00634115870"
        iyz="0"
        izz="0.02399190431" />
    </inertial>
    <visual>
      <origin
        xyz="0 0 0"
        rpy="0 0 0" />
      <geometry>
        <mesh filename="../meshes/base_link.stl" />
      </geometry>
      <material
        name="">
        <color rgba="0.59216 0.61961 0.65098 1" />
      </material>
    </visual>
    <collision>
      <origin
        xyz="0 0 0"
        rpy="0 0 0" />
      <geometry>
        <mesh
          filename="../meshes/base_link.stl" />
      </geometry> 
    </collision>
  </link>
  <link name="L_HipYaw_Link">
    <inertial>
      <origin
        xyz="-0.02955 0 0.06943"
        rpy="0 0 0" />
      <mass value="1.54216" />
      <inertia
        ixx="0.00412070145"
        ixy="0"
        ixz="0.00089593414"
        iyy="0.00664372362"
        iyz="0"
        izz="0.00338413515" />
    </inertial>
    <visual>
      <origin
        xyz="0 0 0"
        rpy="0 0 0" />
      <geometry>
        <mesh
          filename="../meshes/hip_yaw.stl" />
      </geometry>
      <material
        name="">
        <color
          rgba="0.59216 0.61961 0.65098 1" />
      </material>
    </visual>
    <collision>
      <origin
        xyz="0 0 0"
        rpy="0 0 0" />
      <geometry>
        <mesh
          filename="../meshes/hip_yaw.stl" />
      </geometry>
    </collision>
  </link>
  <joint
    name="L_HipYaw"
    type="revolute">
    <origin
      xyz="0 0.105 -0.11190"
      rpy="0 0 0" />
    <parent
      link="base_link" />
    <child
      link="L_HipYaw_Link" />
    <axis
      xyz="0 0 -1" />
    <limit
      effort="100"
      velocity="20" lower="-1." upper="0." />
  </joint>
  <link
    name="L_HipRoll_Link">
    <inertial>
      <origin
        xyz="0.00513 -0.00119 0"
        rpy="0 0 0" />
      <mass
        value="1.16907" />
      <inertia
        ixx="0.00180677428"
        ixy="0.00000973989"
        ixz="0"
        iyy="0.00087972680"
        iyz="0"
        izz="0.00199196267" />
    </inertial>
    <visual>
      <origin
        xyz="0 0 0"
        rpy="0 0 0" />
      <geometry>
        <mesh
          filename="../meshes/hip_roll.stl" />
      </geometry>
      <material
        name="">
        <color
          rgba="0.59216 0.61961 0.65098 1" />
      </material>
    </visual>
    <collision>
      <origin
        xyz="0 0 0"
        rpy="0 0 0" />
      <geometry>
        <mesh
          filename="../meshes/hip_roll.stl" />
      </geometry>
    </collision>
  </link>
  <joint
    name="L_HipRoll"
    type="revolute">
    <origin
      xyz="0 0 0"
      rpy="0 0 0" />
    <parent
      link="L_HipYaw_Link" />
    <child
      link="L_HipRoll_Link" />
    <axis
      xyz="1 0 0" />
    <limit
      effort="200"
      velocity="20" lower="-0.5" upper="1.0" />
  </joint>
  <link
    name="L_HipPitch_Link">
    <inertial>
      <origin
        xyz="0.12203 0.00306 -0.23316"
        rpy="0 0 0" />
      <mass
        value="3.28269" />
      <inertia
        ixx="0.04026422334"
        ixy="-0.00122469549"
        ixz="-0.01390323874"
        iyy="0.04329246922"
        iyz="0.00234011199"
        izz="0.01768138410" />
    </inertial>
    <visual>
      <origin
        xyz="0 0 0"
        rpy="0 0 0" />
      <geometry>
        <mesh
          filename="../meshes/hip_pitch.stl" />
      </geometry>
      <material
        name="">
        <color
          rgba="0.59216 0.61961 0.65098 1" />
      </material>
    </visual>
    <collision>
      <origin
        xyz="0 0 0"
        rpy="0 0 0" />
      <geometry>
        <mesh
          filename="../meshes/hip_pitch.stl" />
      </geometry>
    </collision>
  </link>
  <joint
    name="L_HipPitch"
    type="revolute">
    <origin
      xyz="0 0 0"
      rpy="0 0 0" />
    <parent
      link="L_HipRoll_Link" />
    <child
      link="L_HipPitch_Link" />
    <axis
      xyz="0 1 0" />
    <limit
      effort="800"
      velocity="20" lower="-3.14" upper="3.14" />
  </joint>
  <link
    name="L_KneePitch_Link">
    <inertial>
      <origin
        xyz="0.05276 -0.01856 -0.22635"
        rpy="0 0 0" />
      <mass
        value="2.04524" />
      <inertia
        ixx="0.03535528788"
        ixy="-0.00087858758"
        ixz="-0.00310465960"
        iyy="0.03128221988"
        iyz="0.00677319603"
        izz="0.00677705818" />
    </inertial>
    <visual>
      <origin
        xyz="0 0 0"
        rpy="0 0 0" />
      <geometry>
        <mesh
          filename="../meshes/left_shin.stl" />
      </geometry>
      <material
        name="">
        <color
          rgba="0.59216 0.61961 0.65098 1" />
      </material>
    </visual>
    <collision>
      <origin
        xyz="0 0 0"
        rpy="0 0 0" />
      <geometry>
        <mesh
          filename="../meshes/left_shin.stl" />
      </geometry>
    </collision>
  </link>
  <joint
    name="L_KneePitch"
    type="revolute">
    <origin
      xyz="0.1515 0 -0.339"
      rpy="0 0 0" />
    <parent
      link="L_HipPitch_Link" />
    <child
      link="L_KneePitch_Link" />
    <axis
      xyz="0 1 0" />
    <limit
      effort="800"
      velocity="20" lower="0." upper="3." />
  </joint>
  <link
    name="L_AnklePitch_Link">
    <inertial>
      <origin
        xyz="-0.01035 0.00568 0"
        rpy="0 0 0" />
      <mass
        value="1.18450" />
      <inertia
        ixx="0.00091081511"
        ixy="0.00006964019"
        ixz="0"
        iyy="0.00185149782"
        iyz="0"
        izz="0.00206162879" />
    </inertial>
    <visual>
      <origin
        xyz="0 0 0"
        rpy="0 0 0" />
      <geometry>
        <mesh
          filename="../meshes/left_ankle_pitch.stl" />
      </geometry>
      <material
        name="">
        <color
          rgba="0.59216 0.61961 0.65098 1" />
      </material>
    </visual>
    <collision>
      <origin
        xyz="0 0 0"
        rpy="0 0 0" />
      <geometry>
        <mesh
          filename="../meshes/left_ankle_pitch.stl" />
      </geometry>
    </collision>
  </link>
  <joint
    name="L_AnklePitch"
    type="revolute">
    <origin
      xyz="0.06 0 -0.368"
      rpy="0 0 0" />
    <parent
      link="L_KneePitch_Link" />
    <child
      link="L_AnklePitch_Link" />
    <axis
      xyz="0 1 0" />
    <limit
      effort="500"
      velocity="20" lower="-1.57" upper="1.57" />
  </joint>
  <link
    name="L_AnkleRoll_Link">
    <inertial>
      <origin
        xyz="-0.00989 0 0.07224"
        rpy="0 0 0" />
      <mass
        value="1.42541" />
      <inertia
        ixx="0.00349247764"
        ixy="0"
        ixz="-0.00086859128"
        iyy="0.00816767704"
        iyz="0"
        izz="0.00895530984" />
    </inertial>
    <visual>
      <origin
        xyz="0 0 0"
        rpy="0 0 0" />
      <geometry>
        <mesh
          filename="../meshes/ankle_roll.stl" />
      </geometry>
      <material
        name="">
        <color
          rgba="0.59216 0.61961 0.65098 1" />
      </material>
    </visual>
    <collision>
      <origin
        xyz="0 0 0"
        rpy="0 0 0" />
      <geometry>
        <mesh
          filename="../meshes/ankle_roll.stl" />
      </geometry>
    </collision>
  </link>
  <joint
    name="L_AnkleRoll"
    type="revolute">
    <origin
      xyz="0 0 0"
      rpy="0 0 0" />
    <parent
      link="L_AnklePitch_Link" />
    <child
      link="L_AnkleRoll_Link" />
    <axis
      xyz="1 0 0" />
    <limit
      effort="200"
      velocity="20" lower="-1.0" upper="1.0" />
  </joint>
  <link
    name="R_HipYaw_Link">
    <inertial>
      <origin
        xyz="-0.02955 0 0.06943"
        rpy="0 0 0" />
      <mass
        value="1.54216" />
      <inertia
        ixx="0.00412070145"
        ixy="0"
        ixz="0.00089593414"
        iyy="0.00664372362"
        iyz="0"
        izz="0.00338413515" />
    </inertial>
    <visual>
      <origin
        xyz="0 0 0"
        rpy="0 0 0" />
      <geometry>
        <mesh
          filename="../meshes/hip_yaw.stl" />
      </geometry>
      <material
        name="">
        <color
          rgba="0.59216 0.61961 0.65098 1" />
      </material>
    </visual>
    <collision>
      <origin
        xyz="0 0 0"
        rpy="0 0 0" />
      <geometry>
        <mesh
          filename="../meshes/hip_yaw.stl" />
      </geometry>
    </collision>
  </link>
  <joint
    name="R_HipYaw"
    type="revolute">
    <origin
      xyz="0 -0.105 -0.11190"
      rpy="0 0 0" />
    <parent
      link="base_link" />
    <child
      link="R_HipYaw_Link" />
    <axis
      xyz="0 0 -1" />
    <limit
      effort="100"
      velocity="20" lower="-0." upper="1." />
  </joint>
  <link
    name="R_HipRoll_Link">
    <inertial>
      <origin
        xyz="0.00513 0.00119 0"
        rpy="0 0 0" />
      <mass
        value="1.16907" />
      <inertia
        ixx="0.00180677428"
        ixy="-0.00000973989"
        ixz="0"
        iyy="0.00087972680"
        iyz="0"
        izz="0.00199196267" />
    </inertial>
    <visual>
      <origin
        xyz="0 0 0"
        rpy="0 0 0" />
      <geometry>
        <mesh
          filename="../meshes/hip_roll.stl" />
      </geometry>
      <material
        name="">
        <color
          rgba="0.59216 0.61961 0.65098 1" />
      </material>
    </visual>
    <collision>
      <origin
        xyz="0 0 0"
        rpy="0 0 0" />
      <geometry>
        <mesh
          filename="../meshes/hip_roll.stl" />
      </geometry>
    </collision>
  </link>
  <joint
    name="R_HipRoll"
    type="revolute">
    <origin
      xyz="0 0 0"
      rpy="0 0 0" />
    <parent
      link="R_HipYaw_Link" />
    <child
      link="R_HipRoll_Link" />
    <axis
      xyz="1 0 0" />
    <limit
      effort="200"
      velocity="20" lower="-1.0" upper=".5" />
  </joint>
  <link
    name="R_HipPitch_Link">
    <inertial>
      <origin
        xyz="0.11203 -0.00306 -0.23316"
        rpy="0 0 0" />
      <mass
        value="3.28269" />
      <inertia
        ixx="0.04026423334"
        ixy="0.00122469549"
        ixz="-0.01390323874"
        iyy="0.04329246922"
        iyz="-0.00233982906"
        izz="0.01768138410" />
    </inertial>
    <visual>
      <origin
        xyz="0 0 0"
        rpy="0 0 0" />
      <geometry>
        <mesh
          filename="../meshes/hip_pitch.stl" />
      </geometry>
      <material
        name="">
        <color
          rgba="0.59216 0.61961 0.65098 1" />
      </material>
    </visual>
    <collision>
      <origin
        xyz="0 0 0"
        rpy="0 0 0" />
      <geometry>
        <mesh
          filename="../meshes/hip_pitch.stl" />
      </geometry>
    </collision>
  </link>
  <joint
    name="R_HipPitch"
    type="revolute">
    <origin
      xyz="0 0 0"
      rpy="0 0 0" />
    <parent
      link="R_HipRoll_Link" />
    <child
      link="R_HipPitch_Link" />
    <axis
      xyz="0 -1 0" />
    <limit
      effort="800"
      velocity="20" lower="-3.14" upper="3.14" />
  </joint>
  <link
    name="R_KneePitch_Link">
    <inertial>
      <origin
        xyz="0.05276 0.01856 -0.22635"
        rpy="0 0 0" />
      <mass
        value="2.04524" />
      <inertia
        ixx="0.03537964069"
        ixy="0.00087727444"
        ixz="-0.00310527519"
        iyy="0.03129299830"
        iyz="-0.00676289825"
        izz="0.00679475749" />
    </inertial>
    <visual>
      <origin
        xyz="0 0 0"
        rpy="0 0 0" />
      <geometry>
        <mesh
          filename="../meshes/right_shin.stl" />
      </geometry>
      <material
        name="">
        <color
          rgba="0.59216 0.61961 0.65098 1" />
      </material>
    </visual>
    <collision>
      <origin
        xyz="0 0 0"
        rpy="0 0 0" />
      <geometry>
        <mesh
          filename="../meshes/right_shin.stl" />
      </geometry>
    </collision>
  </link>
  <joint
    name="R_KneePitch"
    type="revolute">
    <origin
      xyz="0.1515 0 -0.339"
      rpy="0 0 0" />
    <parent
      link="R_HipPitch_Link" />
    <child
      link="R_KneePitch_Link" />
    <axis
      xyz="0 -1 0" />
    <limit
      effort="800"
      velocity="20" lower="-3.14" upper="0." />
  </joint>
  <link
    name="R_AnklePitch_Link">
    <inertial>
      <origin
        xyz="-0.01035 0.00568 0"
        rpy="0 0 0" />
      <mass
        value="1.18450" />
      <inertia
        ixx="0.00091077271"
        ixy="-0.00006959439"
        ixz="0"
        iyy="0.00185147541"
        iyz="0"
        izz="0.00206164878" />
    </inertial>
    <visual>
      <origin
        xyz="0 0 0"
        rpy="0 0 0" />
      <geometry>
        <mesh
          filename="../meshes/right_ankle_pitch.stl" />
      </geometry>
      <material
        name="">
        <color
          rgba="0.59216 0.61961 0.65098 1" />
      </material>
    </visual>
    <collision>
      <origin
        xyz="0 0 0"
        rpy="0 0 0" />
      <geometry>
        <mesh
          filename="../meshes/right_ankle_pitch.stl" />
      </geometry>
    </collision>
  </link>
  <joint
    name="R_AnklePitch"
    type="revolute">
    <origin
      xyz="0.06 0 -0.368"
      rpy="0 0 0" />
    <parent
      link="R_KneePitch_Link" />
    <child
      link="R_AnklePitch_Link" />
    <axis
      xyz="0 -1 0" />
    <limit
      effort="500"
      velocity="20" lower="-1.57" upper="1.57" />
  </joint>
  <link
    name="R_AnkleRoll_Link">
    <inertial>
      <origin
        xyz="-0.00989 0 0.07224"
        rpy="0 0 0" />
      <mass
        value="1.42541" />
      <inertia
        ixx="0.00350322410"
        ixy="0"
        ixz="-0.00090168812"
        iyy="0.00816767704"
        iyz="0"
        izz="0.00894456337" />
    </inertial>
    <visual>
      <origin
        xyz="0 0 0"
        rpy="0 0 0" />
      <geometry>
        <mesh
          filename="../meshes/ankle_roll.stl" />
      </geometry>
      <material
        name="">
        <color
          rgba="0.59216 0.61961 0.65098 1" />
      </material>
    </visual>
    <collision>
      <origin
        xyz="0 0 0"
        rpy="0 0 0" />
      <geometry>
        <mesh
          filename="../meshes/ankle_roll.stl" />
      </geometry>
    </collision>
  </link>
  <joint
    name="R_AnkleRoll"
    type="revolute">
    <origin
      xyz="0 0 0"
      rpy="0 0 0" />
    <parent
      link="R_AnklePitch_Link" />
    <child
      link="R_AnkleRoll_Link" />
    <axis
      xyz="1 0 0" />
    <limit
      effort="200"
      velocity="20" lower="-1.0" upper="1.0" />
  </joint>
  <link
    name="WaistPitch_Link">
    <inertial>
      <origin
        xyz="0 0 0.14577"
        rpy="0 0 0" />
      <mass
        value="0.18235" />
      <inertia
        ixx="0.003844"
        ixy="0"
        ixz="0"
        iyy="0.004215"
        iyz="0"
        izz="0.000457" />
    </inertial>
    <visual>
      <origin
        xyz="0 0 0"
        rpy="0 0 0" />
      <geometry>
        <mesh
          filename="../meshes/WaistPitch_Link.stl" />
      </geometry>
      <material
        name="">
        <color
          rgba="0.59216 0.61961 0.65098 1" />
      </material>
    </visual>
    <collision>
      <origin
        xyz="0 0 0"
        rpy="0 0 0" />
      <geometry>
        <mesh
          filename="../meshes/WaistPitch_Link.stl" />
      </geometry>
    </collision>
  </link>
  <joint
    name="WaistPitch"
    type="fixed">  
    <origin
      xyz="0 0 0"
      rpy="0 0 0" />
    <parent
      link="base_link" />
    <child
      link="WaistPitch_Link" />
  </joint>
  <link
    name="WaistYaw_Link">
    <inertial>
      <origin
        xyz="0.0038 -0.00415 0.11424"
        rpy="0 0 0" />
      <mass
        value="14.09938" />
      <inertia
        ixx="0.262766"
        ixy="0"
        ixz="0"
        iyy="0.242504"
        iyz="0"
        izz="0.109346" />
    </inertial>
    <visual>
      <origin
        xyz="0 0 0"
        rpy="0 0 0" />
      <geometry>
        <mesh
          filename="../meshes/WaistYaw_Link.stl" />
      </geometry>
      <material
        name="">
        <color
          rgba="0.59216 0.61961 0.65098 1" />
      </material>
    </visual>
    <visual>
      <origin
        xyz="-0.16 0 0.11"
        rpy="0 0 0" />
      <geometry>
        <box size= "0.09 0.265 0.225"/>
      </geometry>
      <material
        name="">
        <color
          rgba="0.59216 0.61961 0.65098 1" />
      </material>
    </visual>
    <collision>
      <origin
        xyz="0 0 0"
        rpy="0 0 0" />
      <geometry>
        <mesh
          filename="../meshes/WaistYaw_Link.stl" />
      </geometry>
    </collision>
    <collision>
      <origin
        xyz="-0.16 0 0.11"
        rpy="0 0 0" />
      <geometry>
        <box size= "0.09 0.265 0.225"/>
      </geometry>
    </collision>
  </link>
   <joint
    name="WaistYaw"
    type="revolute">
    <origin
      xyz="0 0 0.186"
      rpy="0 0 0" />
    <parent
      link="WaistPitch_Link" />
    <child
      link="WaistYaw_Link" />
    <axis
      xyz="0 0 1" />
    <limit
      effort="100"
      velocity="20" lower="-1." upper="1.0" />
  </joint>
</robot>